Workbook

Sheet Contract Log
A1: Project Name | C1: Address | D1: Estimated Start Date | E1: Estimated Completion Date | F1: Vendor | G1: PO# | H1: Contract Status | I1: Vendor | J1: PO# | K1: Contract Status | L1: Vendor | M1: PO# | N1: Contract Status | O1: Vendor | P1: PO# | Q1: Contract Status | R1: Vendor | S1: PO# | T1: Contract Status
A2: HRP Holbrook | C2: Asheville, NC | D2: 45566 | F2: Zavala | G2: 2411 $243,965 | H2: Fully Executed | I2: Pristine | K2: Fully Executed
A3: Pines at Peach | C3: Raleigh, NC | D3: 45474 | F3: Pristine | G3: 2216 $337,788 | H3: Fully Executed | I3: Zavala-NO PO | L3: Bruzz-NO PO | N3: Fully Executed
A4: Gatebay (Inv 2080/2081/2103) | C4: Henderson, NC | D4: 45566 | E4: 45597 | F4: Pristine | G4: 2378 $38,896 | H4: Fully Executed
A5: Mountain Glen | C5: Brevard, NC | D5: 45536 | F5: Zavala | G5: 2366 $56,964.02 | H5: Fully Executed | I5: Pristine | J5: 2496 $88,825.00 | K5: Fully Executed | L5: Martinez-NO PO | O5: Towa-NO PO | R5: JGBR - Has PO's but not sure how to get this to them now? | V5: Missing info to draft contract
A6: Aaron Mills | C6: Martinsville, VA | D6: 45802 | I6: Pristine-Per OC PO not ready 8/12/25 | J6: Chris 4/28
A7: DHIC: Sedgebrook | C7: Cary, NC | D7: 45658 | F7: Zavala | G7: 2526 | H7: Fully Executed | I7: JSH Windows/Siding | J7: 2862/2863 | K7: Fully Executed | L7: Anzola Trim-NO PO
A8: DHIC: Jeffries Ridge (Alli) | C8: Raleigh, NC | D8: 45627 | F8: Zavala | G8: 2523 | H8: Fully Executed | I8: Pristine | J8: 2842 $201,646.00 | K8: Fully Executed | L8: CIE (interior) | M8: 2557 $26,226.00 *PO had note 'need to be edited' - emailed OC 6/25 | O8: Towa | P8: no PO in QB | V8: Created - Awaiting Signatures
A9: DHIC: Ripley Station (Starting interior & siding July 2025) | C9: Raleigh, NC | F9: Zavala | G9: 2525 | H9: Fully Executed | I9: Rubio & Pristine | J9: 3170, 3243, 3246-Rubio; 3244, 3245 Pristine | K9: Rubio 3170 Fully Executed; Pristine 3244 Fully Executed; Rubio 3243 Fully Executed; Pristine 3403 Fully Executed; Rubio 3246 Fully Executed; Pristine 3245 created by SA and awaiting signatures | L9: Anzola Trim (Joe) wait for PO | O9: Towa-NO PO | R9: Amber | S9: NO PO# | T9: Created - Awaiting Signatures | V9: Sub Executed - Need Wesco Signatures
A10: DHIC: Madison Glen | C10: Raleigh, NC | F10: Zavala | G10: 2524 & 3883 | H10: Fully Executed | I10: Pristine (Siding & WIndows) | J10: 3884 | K10: Created - Awaiting Signatures | L10: Anzola Trim (Joe) wait for PO | O10: Towa-NO PO | V10: Fully Executed
A11: DHIC: Avonlea Apartments | C11: Raleigh, NC | D11: 45658 | F11: Zavala | G11: 2521 | H11: Fully Executed | I11: Rubio Siding/Windows | J11: 2960 $286,564.00 3062 $24,045.00 | K11: Fully Executed | L11: Anzola Trim (Joe) wait for PO | O11: Towa-NO PO | R11: JSH - NO PO | V11: To Be Completed
A12: DHIC: Tryon Grove | C12: Raleigh, NC | F12: Zavala-8/12 OC checking PO - 9/24/25 Updated to Rooster Roofing RK | G12: Rooster Roofing 3322 | H12: Fully Executed | I12: JSH Windows/Siding Gave to Joe 8/7/25 & 9/3/25 | J12: 3164, 3188, 3167, 3190 | K12: Created - Awaiting Signatures | L12: Pristine | M12: 3163-Bldg 2500 only | N12: Fully Executed | O12: Towa-NO PO | R12: JSH chase
A13: DHIC: Highland Village | C13: Cary, NC | F13: Zavala | G13: 2522 | H13: Fully Executed | I13: TBD Siding | L13: CIE (interior) or Anzola | O13: Towa-NO PO
A14: Bond Deal 3: Ridgeway (not started - Aug/Sept 2025 start) | C14: Taylorsville, NC | F14: Zavala | G14: 2443 (Oscar to follow up 6/18) | H14: Created - Awaiting Signatures | L14: Bruzz? | O14: Towa-NO PO
A15: Bond Deal 3: Brookside | C15: Maxton, NC | F15: Pristine | G15: 2720? Note: SA need OC help | I15: Anzola/Martinez | L15: Guillermo Shutters
A16: Bond Deal 3: Berry Park | C16: Chadbourn, NC | I16: Bruzz Interior | L16: Guillermo Shutters | O16: Towa-NO PO
A17: Bond Deal 3: Chadwick Place | C17: Chadbourn, NC | I17: Bruzz Interior | L17: Guillermo Shutters - not set up
A18: Bond Deal 3: Piney Pointe | C18: Hamlet, NC | I18: Martinez | O18: Towa-NO PO
A19: Bond Deal 3: Brittany Place | C19: Washington, NC | I19: Martinez | L19: Bruzz
A20: Bond Deal 3: British Woods ************ This is where we start again 6/26**** | C20: Roanoke Rapids, NC
A21: Bond Deal 3: Burnside Village | C21: Hookertown, NC | I21: Martinez | L21: Bruzz? | O21: Towa-NO PO
A22: Bond Deal 3: Gooden Village | C22: Elizabethcity, NC | L22: Anzola Trim (Joe) | O22: Towa-NO PO
A23: Bond Deal 3: Pine Ridge | C23: Avery, NC
A24: Bond Deal 3: Ridgeview | C24: Sparta, NC
A25: Bond Deal 3: Ridgeway | C25: Taylorsville, NC | F25: Amber Construction | G25: 3948 (OLD) | H25: Created - Awaiting Signatures | I25: Bruzz-gave to CO 5/15 | J25: 4044 | K25: Created - Awaiting Signatures | L25: Amber emailed 5/15 | M25: 4045 | N25: Fully Executed
A26: Bond Deal 3: River Park | C26: Sylva, NC
A27: Bond Deal 3: Scotland Arms | C27: Scotland Neck, NC
A28: Bond Deal 3: Woodfield | C28: Fairmont, NC
A29: Partnership: Park Place Apartments | C29: Snow Hill, NC
A30: Partnership: Crest Knolls | C30: Taylorsville, NC
A31: Partnership: Gatebay Apartments | C31: Conway, NC
A32: Partnership: Regal Oaks | C32: Hendersonville, NC
A33: Partnership: Greenfield Manor | C33: Mullins, SC | F33: Amber Construction | G33: 3903 | H33: Fully Executed
A34: Brian Dloniak | C34: GSO, NC | F34: Zavala | G34: NO PO# | H34: Fully Executed
A35: Partnership: British Woods | C35: Roanoke Rapids, NC | F35: Zavala-emailed 5/15 | G35: 4051 | H35: Fully Executed
A36: Partnership: Colony Woods | C36: Roanoke Rapids, NC | F36: Zavala-emailed 5/15 | G36: 4050 | H36: Fully Executed
A37: Partnership: Long Branch | C37: Dillon, SC | F37: Bruzz | G37: PO# 4033 | H37: Fully Executed | I37: Amber emailed 5/15 | J37: 4048 | K37: Fully Executed
A38: Partnership: Mill Pond | C38: Dillon, SC | F38: Bruzz | G38: 4025 | H38: Fully Executed | I38: Amber | J38: 4024 | K38: Fully Executed
A39: Partnership: Silver Trace | C39: Marion, SC | F39: Amber Construction | G39: NO PO# | H39: Fully Executed
A40: Partnership: River Bend | C40: Fair Bluff, NC | F40: Amber Construction | G40: PO# 4086-6/4 emailed to Amber | H40: Fully Executed
...

Sheet Estimate and Scheduling Req
A1: Customer | B1: 1st Contact | C1: Property | D1: Location | E1: Scope
A2: Partnership - Jennifer Hatcher | B2: 45750 | C2: Greenfield Manor | D2: Mullins, SC | E2: PM: Can you price the windows for this building 193. Building 191 and 195 are brick with wooden gables. I’d like to finish that street off and move around to 1101 is all wooden and 1103 is brick with wooden gables. RESPONSE:I do have a question. Only Windows for Building 193, siding is complete. Are the rest of the buildings on the street side 191,195,1101,11,03,1105,1107 needing the windows as well as we do siding? Are we doing 1105 & 1107? PM: Yes, siding and windows for those units.
A3: Partnership - Kellie Atkins | B3: 45777 | C3: Mallard Creek | D3: Auroura, NC 27806 | E3: Replace 22 exterior storage doors - 36 X 80 (Photo to right)
A4: Partnership - Kellie Atkins | B4: Estimate Provided-waiting on approval | C4: Park Place | D4: Snow Hill, NC | E4: $26K Quote
A5: Partnership - Kellie Atkins | B5: 45775 | C5: Park Place | D5: Snow Hill, NC | E5: We also have an existing gazebo there that the floor needs to be replaced however I would like to get a quote to fill in the hole under it with concrete and just build a new shelter. If I could get quotes separately that would be great .
A6: Partnership - Nadia Gallovich | B6: Work approved 5/2/25 - Need dates for contract $110,250 | C6: Wilmington Court | D6: Wallace, NC | E6: 160 window replacements
A7: Partnership - Nadia Gallovich | B7: 45798 | C7: Oak Ridge | D7: Wallace, NC | E7: 16 breezeway windows replaced
A8: Partnership - Tracy Young | B8: Estimate Provided-waiting on approval | C8: Palmetto | E8: Siding & Windows - 7/8/25 added shutter request
A9: Partnership - Jennifer Hatcher | C9: Gatebay | D9: Conway, SC | E9: Gate Bay over bldg. 11 and 12 in Conway. (photo to right)
A11: Partnership | C11: Pinetree Apartments? | D11: Oxford, NC

Sheet Vehicle Log-1st Meeting
A1: Year | B1: Model/Make | C1: Driver | D1: Plate # | E1: Title last 5 digits | F1: Vin # | G1: Renewal Date | H1: Paid Date | I1: Interest Rate | J1: Notes:
A2: 2016 | B2: Silverado C2500 | C2: Service Truck | D2: JK8642 | E2: 65372 | F2: 1GB1CUE82GF269081 | G2: 45657 | H2: 45664
A3: 2019 | B3: Chevy 3500 Dually | C3: Wes Atkinson | D3: JR1324 | E3: 29941 | F3: 1GC4KXEY9KF129941 | G3: 45688 | H3: 45627
A4: 2024 | B4: Toyota Tundra | C4: Chris OKeefe | D4: LAL9805 | E4: 85175 | F4: 5TFKB5DB3RX185175 | G4: 45869 | I4: 0.0879 | J4: Need 2nd key fob from dealer
A5: 2024 | B5: Toyota Rav 4 | C5: Oscar Centeno | D5: LAM1425 | E5: 77918 | F5: 2T3H1RFVXRC277918 | G5: 45869 | H5: 45804 | I5: 0.0449
A6: 2017 | B6: Chevy Suburban | C6: Wes Atkinson | D6: FFJ8206 | E6: 33947 | F6: 1GNSKJKC2HR284780 | G6: 45838
A7: 2020 | B7: Chevy Silverado 2500 | C7: Jesse Warren | D7: KB9444 | E7: 97947 | F7: 1GC1YLEY3LF245650 | G7: 45869 | H7: 45863
A8: 2024 | B8: Toyota Tundra | C8: Joe St. John | D8: LEJ5502 | E8: 26165 | F8: 5TFLA5DBXRX228031 | G8: 46022 | H8: 45627 | I8: 0.0499
A9: 2017 | B9: Chevy Truck | C9: Chuck Atkinson | D9: EHB4862 | E9: 40947 | F9: 1GCVKREC6HZ169664 | G9: 45688 | J9: 2/2025 Wrecked
A10: 2017 | B10: Cadillac Escalade | C10: Evie Atkinson | F10: 1GYS4HKJ9HR385416
A14: Year | B14: Model/Make | C14: Driver | D14: Last Oil Change Date/Mileage | E14: Other Service/Date
A15: 2016 | B15: Silverado C2500 | C15: Service Truck
A16: 2019 | B16: Chevy 3500 Dually | C16: Wes Atkinson
A17: 2017 | B17: Chevy Suburban | C17: Wes Atkinson
A18: 2024 | B18: Toyota Tundra | C18: Chris OKeefe
A19: 2024 | B19: Toyota Rav 4 | C19: Oscar Centeno
A20: 2020 | B20: Chevy Silverado 2500 | C20: Jesse Warren
A21: 2024 | B21: Toyota Tundra | C21: Joe St. John
A22: 2017 | B22: Chevy Truck | C22: Chuck Atkinson
A23: 2017 | B23: Cadillac Escalade | C23: Evie Atkinson

Sheet 6.4.26
A1: 2025 Wesco Notebook | C1: Topics | D1: Team Meeting 6.3.26 Present: Wes, Stephanie, Oscar, Joe, Chris, Rebecca
C2: 1.) | D2: Do we need any contracts for subcontractors? Turn in subcontractor recipts, Review Towa, Martinez, Bruzz
C3: 2.) | D3: Scope
C4: 3.) | D4: Contract Request
C5: 4.)
C6: 5.)
B8: PROJECT SUMMARY | R8: Be sure to include the job name, building number, and/or unit number on the invoice.
B9: Project Name | C9: Customer/ Owner | D9: Start Date | E9: Estimated Job Completion Date | F9: SharePoint Link | G9: Proj Mgr | H9: Scope | I9: Subcontractor & Schedule THIS WEEK | J9: Subcontractor & Schedule NEXT WEEK/FUTURE | K9: Date Inventory Recorded | L9: Weekly Job Summary (Materials Ordered/Arrival Date/Work Performed/Action Taken) | M9: PM Action Items Next Week (Change Order Submission Needed/Unsafe Conditions/Materials/Opportuities) | N9: Others Action Items | O9: Customer Contracts Executed | P9: EXECUTED SUBCONTRACTS
B10: BD3 Ridgeway | C10: KMW | D10: TBD | E10: TBD | G10: Chris | H10: build lean to | L10: Build mailbox addition on maintenance shed. Spoke with Heitor waiting on architect/owners to decide DRAFT CO# 1786 $0.99 | M10: Follow- up | N10: RK contract
B11: Concord | C11: KMW | D11: 46174 | E11: 46388 | F11: Link | G11: Chris 8989 | H11: Interior/Exterior | L11: EST 1568 - in Oscar's court - sections have been sent to him
B12: DHIC Avonlea HILLSTONE WORK | C12: KMW | D12: 45717 | E12: 46191 | G12: Joe | L12: Wesco retention billed 6/5 - Hillstone contract was closed, but reopened so they could bill for rails at dumpster area due to sidewalk slope, Window sash to be replaced 5017 2unit 201 by Pristine 6-18
B13: DHIC Highland | C13: KMW | D13: 45992 | E13: 46203 | G13: Joe | L13: Fence on top of block wall Window opening control device on windows! | M13: PO 3480 - HC Door Order - swing per plans
B14: DHIC Madison Glen | C14: KMW | D14: 46054 | E14: 46220 | G14: Joe | L14: Pristine-Siding the office, 6800, and 6820. Rigo to finish framing 6-19-26. Punch work completed on 7 buildings, will need to add new blinds at 6820 after windows get replaced | N14: Ord 4.14.26 Trucks 6, 7 est del by 5/7 , waiting on ETA for 10, 11 Ordered SA - We have no profit here...review pay app
B15: DHIC Ripley | C15: KMW | D15: 45931 | E15: 46233 | G15: Joe | L15: Stairs are raised for epoxy and need to get rails replaced
B16: DHIC Sedgebrook* | C16: KMW | D16: 45778 | E16: 46203 | G16: Joe | L16: Need to get dumpster fences installed-cleared after 6-18-26
B17: DHIC Tryon | C17: KMW | D17: 45839 | E17: 46142 | G17: Joe | L17: Additional areas were worked with epoxy, will require Pristine to return next week to remove siding and install flashing and siding again. CO 1793 In Procore passed inspections 5/7/26 and will complete this work the week of 5/11 CO 1795 In Procore -6 thresholds and door shoes for riser rooms after doors were cut down for concrete In Procore Door shoes have been installed, will install thresholds this week when we return for siding installation.
B19: River Bend | C19: Partnership
B20: Green Valley | C20: HRP | F20: Link | G20: Chris 8989 | H20: Siding | N20: Are we invoicing for elevator pits or will that be in the contract?
B21: Greenfield | C21: Partnership | D21: 46118 | F21: Link | G21: Chris | H21: Siding / Windows | O21: YES | P21: YES Amber
B22: Holbrook | C22: HRP | D22: 45566 | E22: 46174 | F22: Home | G22: Chris | H22: Siding/Roof/Gutter | I22: Pristine M-F | J22: Pristine M-F | L22: Need to get a very accurate inventory of what's on the ground and in trailers. Would like to consolidate. | M22: CO 1772 Draft | N22: RK - Any retention updates for upcoming 5/15 billing - next building? | O22: YES | P22: YES Zavala & YES Pristine
B23: Lakeview | C23: Partnership | D23: 46139 | E23: /15/26 | F23: Link | G23: Chris | H23: Exterior | O23: YES
B24: Long Branch | C24: Partnership | F24: Link | G24: Chris | H24: Exterior | O24: YES
B25: Martins Landing | C25: Partnership | D25: 46091 | F25: Link | G25: Chris | H25: Roof | O25: YES | P25: NO
B26: Maynard - APS | C26: KMW | D26: 45839 | F26: Link | G26: Wes | H26: Siding
B27: Meadowview | C27: KMW | D27: 45901 | F27: Link | G27: Chris | H27: Exterior & Interior | L27: We are giving an estimate for Siding for this job as well
B28: Mill Pond | C28: Partnership | D28: 46139 | E28: 46157 | F28: Link | G28: Chris | H28: Exterior | O28: YES
B29: Palmetto | C29: Partnership | D29: 46097 | F29: Link | G29: Chris | H29: Siding / Windows
B30: River Park | C30: KMW | G30: Chris
B31: Scotland | C31: KMW | G31: Joe
B32: Silver Trace | C32: Partnership | F32: Silver Trace WescoSOW & Estimate.xlsx | L32: We have a contract for this, but no start dates and it is not on the team meeting notes | O32: Need dates
B33: Greenfield Manor
B34: Silver Trace
B35: Berry Court | C35: Partnership | D35: 46181 | E35: 46185 | L35: we will need to go back to finish this
B37: Upcoming Projects | C37: Customer/ Owner | D37: EstimatedStart Date | E37: Estimated Job Completion Date | F37: SharePoint Link | G37: Proj Mgr | H37: Scope | I37: Subcontractor & Schedule THIS WEEK | J37: Subcontractor & Schedule NEXT WEEK/FUTURE | K37: Date Inventory Recorded
B38: Palmetto | C38: Partnership | H38: Siding / Windows
B45: Pipeline/Bids | C45: Customer/ Owner | D45: Estimated Start Date | E45: Estimated Job Completion Date | F45: SharePoint Link | G45: Proj Mgr | H45: Scope
B46: Mock Place | C46: KMW | D46: TBD | H46: Reno
B47: James A Walker | C47: KMW | D47: TBD | H47: Interior Reno & some Exterior
B48: Gatebay II | C48: Partnership | D48: TBD | H48: Siding
B49: Green Valley | C49: HRP | D49: TBD | H49: Siding
...

Sheet To Do
B1: Task Summary
B2: Project Name | C2: Proj Mgr | D2: PM Action Items Next Week (Change Order Submission Needed/Unsafe Conditions/Materials/Opportuities) | E2: Others Action Items
B3: ='6.4.26'!B10 -> BD3 Ridgeway | C3: ='6.4.26'!G10 -> Chris | D3: ='6.4.26'!M10 -> Follow- up | E3: ='6.4.26'!N10 -> RK contract
B4: ='6.4.26'!#REF! -> #REF! | C4: ='6.4.26'!#REF! -> #REF! | D4: ='6.4.26'!#REF! -> #REF! | E4: ='6.4.26'!#REF! -> #REF!
B5: ='6.4.26'!#REF! -> #REF! | C5: ='6.4.26'!#REF! -> #REF! | D5: ='6.4.26'!#REF! -> #REF! | E5: ='6.4.26'!#REF! -> #REF!
B6: ='6.4.26'!B11 -> Concord | C6: ='6.4.26'!G11 -> Chris 8989 | D6: ='6.4.26'!M11 -> 0 | E6: ='6.4.26'!N11 -> 0
B7: ='6.4.26'!B12 -> DHIC Avonlea HILLSTONE WORK | C7: ='6.4.26'!G12 -> Joe | D7: ='6.4.26'!M12 -> 0 | E7: ='6.4.26'!N12 -> 0
B8: ='6.4.26'!B13 -> DHIC Highland | C8: ='6.4.26'!G13 -> Joe | D8: ='6.4.26'!M13 -> PO 3480 - HC Door Order - swing per plans | E8: ='6.4.26'!N13 -> 0
B9: ='6.4.26'!B14 -> DHIC Madison Glen | C9: ='6.4.26'!G14 -> Joe | D9: ='6.4.26'!M14 -> 0 | E9: ='6.4.26'!N14 -> Ord 4.14.26 Trucks 6, 7 est del by 5/7 , waiting on ETA for 10, 11 Ordered SA - We have no profit here...review pay app
B10: ='6.4.26'!B15 -> DHIC Ripley | C10: ='6.4.26'!G15 -> Joe | D10: ='6.4.26'!M15 -> 0 | E10: ='6.4.26'!N15 -> 0
B11: ='6.4.26'!B16 -> DHIC Sedgebrook* | C11: ='6.4.26'!G16 -> Joe | D11: ='6.4.26'!M16 -> 0 | E11: ='6.4.26'!N16 -> 0
B12: ='6.4.26'!B17 -> DHIC Tryon | C12: ='6.4.26'!G17 -> Joe | D12: ='6.4.26'!M17 -> 0 | E12: ='6.4.26'!N17 -> 0
B13: ='6.4.26'!B18 -> 0 | C13: ='6.4.26'!G18 -> 0 | D13: ='6.4.26'!M18 -> 0 | E13: ='6.4.26'!N18 -> 0
B14: ='6.4.26'!B19 -> River Bend | C14: ='6.4.26'!G19 -> 0 | D14: ='6.4.26'!M19 -> 0 | E14: ='6.4.26'!N19 -> 0
B15: ='6.4.26'!B20 -> Green Valley | C15: ='6.4.26'!G20 -> Chris 8989 | D15: ='6.4.26'!M20 -> 0 | E15: ='6.4.26'!N20 -> Are we invoicing for elevator pits or will that be in the contract?
B16: ='6.4.26'!B21 -> Greenfield | C16: ='6.4.26'!G21 -> Chris | D16: ='6.4.26'!M21 -> 0 | E16: ='6.4.26'!N21 -> 0
B17: ='6.4.26'!B22 -> Holbrook | C17: ='6.4.26'!G22 -> Chris | D17: ='6.4.26'!M22 -> CO 1772 Draft | E17: ='6.4.26'!N22 -> RK - Any retention updates for upcoming 5/15 billing - next building?
... B29: ='6.4.26'!B34 -> Silver Trace | C29: ='6.4.26'!G34 -> 0 | D29: ='6.4.26'!M34 -> 0 | E29: ='6.4.26'!N34 -> 0
B30: ='6.4.26'!B36 -> 0 | C30: ='6.4.26'!G36 -> 0 | D30: ='6.4.26'!M36 -> 0 | E30: ='6.4.26'!N36 -> 0
B31: ='6.4.26'!B37 -> Upcoming Projects | C31: ='6.4.26'!G37 -> Proj Mgr | D31: ='6.4.26'!M37 -> 0 | E31: ='6.4.26'!N37 -> 0
B32: ='6.4.26'!B38 -> Palmetto | C32: ='6.4.26'!G38 -> 0 | D32: ='6.4.26'!M38 -> 0 | E32: ='6.4.26'!N38 -> 0
B33: ='6.4.26'!B39 -> 0 | E33: ='6.4.26'!N39 -> 0
B34: ='6.4.26'!B40 -> 0 | E34: ='6.4.26'!N40 -> 0
B35: ='6.4.26'!B41 -> 0 | E35: ='6.4.26'!N41 -> 0
E36: ='6.4.26'!N42 -> 0

Sheet 6.26.25
B2: Team Meeting
B3: 6.26.25
B4: Present: Wes, Oscar, Joe, Carson & Stephanie & Rebecca (Septet Team, PRESENT)
B5: Topics
B6: 1.) | C6: Colonial Life @ 12
B7: 2.) | C7: Contract Log
B8: 3.) | C8: Estimate/Scheduling
B9: 4.) | C9: Invoice review - Inventory
B10: 5.) | C10: Oil changes and tires
B11: 6.) | C11: Weekly: Sub calendar update/Daily Job Sheets/Photos Uploaded
B12: 7.) | C12: Pay Apps
B13: 8.)
B14: 9.)
B15: PROJECTS | L15: Be sure to include the job name, building number, and/or unit number on the invoice.
B16: Current Projects (Start Date) | C16: Project Manager (always Chris) | D16: Subcontractor & Schedule THIS WEEK | E16: Subcontractor & Schedule NEXT WEEK/FUTURE | F16: Date Inventory Recorded | G16: Weekly Job Summary (Materials Ordered/Arrival Date/Work Performed/Action Taken) | H16: Action Items Next Week (Change Order Submission Needed/Unsafe Conditions/Materials/Opportuities) | I16: Estimated Job Completion Date | J16: CONTRACTS
B17: HRP Brightwood (4/2023) | C17: x | D17: Pristine | G17: Punch lists for Building 7 & 8 are ready, still waiting on the list from HRP to close out 5 & 6. When we have Siks guys back out there they need to seal the gutter that is leaking on 5. Chris will schedule them for later this week. We also need to get some siding to replace the wall they have been pulling off of in Building 10. | H17: Need to get the siding to replenish the wall they have been pulling off of, also get them scheduled to start the punch work. | I17: 45505 | J17: Done
B18: Pines @ Peach | C18: Joe | D18: Pristine | G18: Outside of 3 done / Working on Outside of 2 - KMW has Pissed off the owners. Change order for Ceilings at top floors & Breezeways has been approved. 2 crews are working on re-insulating the windows on backside on buildings 3 and 2 Also have the same crews working on the breezeways Along with putting in flashing and 2x10 in place (flashing taped and flex taped all joints along with ty-vec work) (Porches are back flush on buildings 2 & 3) | H18: CHANGE ORDERS??? | J18: Done
B19: Mountain Glen | C19: x | D19: Pristine / Rigo | G19: Rigo was installing doors in the UFAS units, sample walls for siding have been hung on building 144 for viewing. Siding order will ship 12/3 and will arrive 12/5 - 12/6. Last truck of doors was delivered by Sik Sunday 12/1. Consolidate containers on site so that we have room to store our siding, and need to be prepared to unload siding when it arrives. | H19: Need to find out what JGBR will be doing at Mountain Glen with Phillip, weather it is exterior work or interior work. Confirm if exterior doors are in the trailer Sik hauled up Sunday.
B20: Holbrook | C20: x | D20: Pristine / Zavala | G20: Zavala has his guys starting to felt Building 3 (Type 3). They have shingles on all amenities and garages. Building 2 also has shingles on it and now needs only the metal roofing. Jonathan also has sent us the material list for the metal he will be needing. | H20: Call Jonathan, and make sure he has guys on site to unload truck of siding. (Carefully)
B21: Dloniak House | C21: Crawl Diddy | D21: Pinnacle | G21: Huntley - Bricking Chimney & House , PEM (plumbing)- waiting on tubs / (electrical) - lighting in kitchen and porches / (HVAC) - relocating lines & gas lines, Steve (Pro Chem) - after PME finished | H21: Inspections? Getting tied into city- Hub cast iron? Gas Lines? Temp power? Structural Protection infront of plumbing fixtures in garages
B22: Woodfield - BD3 | C22: Joe | G22: Should finish 3/7/25
B23: Aaron Mills | D23: Pristine
B24: Jeffries -DHIC | C24: Joe
B25: Avonlea - DHIC | C25: Joe
B26: Sedgbrook - DHIC | C26: Joe
B27: Piney Pointe - BD3 | C27: Joe
B28: Brookside - BD3 | C28: Joe
B29: Burnside - BD3 | C29: Joe
B30: Brittany Place - BD3 | C30: Joe
B31: Scotland Arms - BD3 | C31: Joe
B32: British Arms - BD3 | C32: Joe
B33: River Park - BD3 | E33: Rigo | G33: Monday - 6-23-25 Rigo starting UFAS units 6 & 16 Demo & Framing
B34: Upcoming Projects (Start Date) | C34: Project Manager | D34: Subcontractor | F34: Customer Contact | G34: Weekly Planning Summary (Materials Ordered/Arrival Date/Change Order Submission Needed/Unsafe Conditions/Opportuities) | H34: Action Items This Week | I34: Estimated Start Date
B35: Tryon- DHIC | C35: Joe
B36: Ripley - DHIC | C36: Joe
B37: Highland Village- DHIC | C37: Joe
B38: Madison Glen - DHIC | C38: Joe
B39: Pine Ridge- BD3
B40: Pine View- BD3
B41: Ridgeway- BD3
...

Sheet 6.19.25
B2: Team Meeting
B3: 6.19.25
B4: Present: Wes, Oscar, Joe, Carson & Stephanie & Rebecca (Septet Team, PRESENT)
B5: Topics
B6: 1.) | C6: Weekly: Sub calendar update/Daily Job Sheets/Photos Uploaded
B7: 2.) | C7: Contract Log
B8: 3.) | C8: BCBS 7.1 Renewal
B9: 4.) | C9: Invoice review - Inventory
B10: 5.) | C10: Oil changes and tires
B11: 6.) | C11: Change Order Review & New Process - need info/email to right
B12: 7.) | C12: OneStep GPS Tracker
B13: 8.) | C13: Reminder - Add notes in memo line of estimate/CO emailed to customer
B14: 9.)
B15: PROJECTS | L15: Be sure to include the job name, building number, and/or unit number on the invoice.
B16: Current Projects (Start Date) | C16: Project Manager (always Chris) | D16: Subcontractor & Schedule THIS WEEK | E16: Subcontractor & Schedule NEXT WEEK/FUTURE | F16: Date Inventory Recorded | G16: Weekly Job Summary (Materials Ordered/Arrival Date/Work Performed/Action Taken) | H16: Action Items Next Week (Change Order Submission Needed/Unsafe Conditions/Materials/Opportuities) | I16: Estimated Job Completion Date | J16: CONTRACTS
B17: HRP Brightwood (4/2023) | C17: Chris | D17: Pristine | G17: Punch lists for Building 7 & 8 are ready, still waiting on the list from HRP to close out 5 & 6. When we have Siks guys back out there they need to seal the gutter that is leaking on 5. Chris will schedule them for later this week. We also need to get some siding to replace the wall they have been pulling off of in Building 10. | H17: Need to get the siding to replenish the wall they have been pulling off of, also get them scheduled to start the punch work. | I17: 45505 | J17: Done
B18: Pines @ Peach | C18: Joe | D18: Pristine | G18: Outside of 3 done / Working on Outside of 2 - KMW has Pissed off the owners. Change order for Ceilings at top floors & Breezeways has been approved. 2 crews are working on re-insulating the windows on backside on buildings 3 and 2 Also have the same crews working on the breezeways Along with putting in flashing and 2x10 in place (flashing taped and flex taped all joints along with ty-vec work) (Porches are back flush on buildings 2 & 3) | H18: CHANGE ORDERS??? | J18: Done
B19: Mountain Glen | C19: Chris | D19: Pristine / Rigo | G19: Rigo was installing doors in the UFAS units, sample walls for siding have been hung on building 144 for viewing. Siding order will ship 12/3 and will arrive 12/5 - 12/6. Last truck of doors was delivered by Sik Sunday 12/1. Consolidate containers on site so that we have room to store our siding, and need to be prepared to unload siding when it arrives. | H19: Need to find out what JGBR will be doing at Mountain Glen with Phillip, weather it is exterior work or interior work. Confirm if exterior doors are in the trailer Sik hauled up Sunday.
B20: Holbrook | C20: Chris | D20: Pristine / Zavala | G20: Zavala has his guys starting to felt Building 3 (Type 3). They have shingles on all amenities and garages. Building 2 also has shingles on it and now needs only the metal roofing. Jonathan also has sent us the material list for the metal he will be needing. | H20: Call Jonathan, and make sure he has guys on site to unload truck of siding. (Carefully)
B21: Dloniak House | C21: Crawl Diddy | D21: Pinnacle | G21: Huntley - Bricking Chimney & House , PEM (plumbing)- waiting on tubs / (electrical) - lighting in kitchen and porches / (HVAC) - relocating lines & gas lines, Steve (Pro Chem) - after PME finished | H21: Inspections? Getting tied into city- Hub cast iron? Gas Lines? Temp power? Structural Protection infront of plumbing fixtures in garages
B22: Woodfield - BD3 | C22: Joe | G22: Should finish 3/7/25
B23: Aaron Mills | D23: Pristine
B24: Jeffries -DHIC | C24: Joe
B25: Avonlea - DHIC | C25: Joe
B26: Sedgbrook - DHIC | C26: Joe
B27: Piney Pointe - BD3 | C27: Joe
B28: Brookside - BD3 | C28: Joe
B29: Burnside - BD3 | C29: Joe
B30: Brittany Place - BD3 | C30: Joe
B31: Scotland Arms - BD3 | C31: Joe
B32: British Arms - BD3 | C32: Joe
B33: River Park - BD3 | E33: Rigo | G33: Monday - 6-23-25 Rigo starting UFAS units 6 & 16 Demo & Framing
B34: Upcoming Projects (Start Date) | C34: Project Manager | D34: Subcontractor | F34: Customer Contact | G34: Weekly Planning Summary (Materials Ordered/Arrival Date/Change Order Submission Needed/Unsafe Conditions/Opportuities) | H34: Action Items This Week | I34: Estimated Start Date
B35: Tryon- DHIC | C35: Joe
B36: Ripley - DHIC | C36: Joe
B37: Highland Village- DHIC | C37: Joe
B38: Madison Glen - DHIC | C38: Joe
B39: Pine Ridge- BD3
B40: Pine View- BD3
B41: Ridgeway- BD3
...

Sheet 5.21.25
B2: Team Meeting
B3: 5.21.25
B4: Present: Wes, Oscar, Joe, Carson & Stephanie & Rebecca (Septet Team, PRESENT)
B5: Topics
B6: 1.) | C6: Weekly: Sub calendar update/Daily Job Sheets/Photos Uploaded
B7: 2.) | C7: Contract Log
B8: 3.) | C8: Yale front door codes?
B9: 4.) | C9: Invoice review - Inventory
B10: 5.) | C10: Dario - RK Emailed him 3x, SA texted him daily - still no paperwork - he is not authorized to be onsite yet
B11: 6.) | C11: Change Order Review & New Process - need info/email to right
B12: 7.) | C12: OneStep GPS Tracker
B13: 8.) | C13: Reminder - Add notes in memo line of estimate/CO emailed to customer
B14: 9.)
B15: PROJECTS | L15: Be sure to include the job name, building number, and/or unit number on the invoice.
B16: Current Projects (Start Date) | C16: Project Manager (always Chris & Joe) | D16: Subcontractor & Schedule THIS WEEK | E16: Subcontractor & Schedule NEXT WEEK/FUTURE | F16: Date Inventory Recorded | G16: Weekly Job Summary (Materials Ordered/Arrival Date/Work Performed/Action Taken) | H16: Action Items Next Week (Change Order Submission Needed/Unsafe Conditions/Materials/Opportuities) | I16: Estimated Job Completion Date | J16: CONTRACTS
B17: HRP Brightwood (4/2023) | C17: Chris | D17: Pristine | G17: Punch lists for Building 7 & 8 are ready, still waiting on the list from HRP to close out 5 & 6. When we have Siks guys back out there they need to seal the gutter that is leaking on 5. Chris will schedule them for later this week. We also need to get some siding to replace the wall they have been pulling off of in Building 10. | H17: Need to get the siding to replenish the wall they have been pulling off of, also get them scheduled to start the punch work. | I17: 45505 | J17: Done
B18: Pines @ Peach | C18: Joe | D18: Pristine | G18: Outside of 3 done / Working on Outside of 2 - KMW has Pissed off the owners. Change order for Ceilings at top floors & Breezeways has been approved. 2 crews are working on re-insulating the windows on backside on buildings 3 and 2 Also have the same crews working on the breezeways Along with putting in flashing and 2x10 in place (flashing taped and flex taped all joints along with ty-vec work) (Porches are back flush on buildings 2 & 3) | H18: CHANGE ORDERS??? | J18: Done
B19: Mountain Glen | C19: Chris | D19: Pristine / Rigo | G19: Rigo was installing doors in the UFAS units, sample walls for siding have been hung on building 144 for viewing. Siding order will ship 12/3 and will arrive 12/5 - 12/6. Last truck of doors was delivered by Sik Sunday 12/1. Consolidate containers on site so that we have room to store our siding, and need to be prepared to unload siding when it arrives. | H19: Need to find out what JGBR will be doing at Mountain Glen with Phillip, weather it is exterior work or interior work. Confirm if exterior doors are in the trailer Sik hauled up Sunday.
B20: Holbrook | C20: Chris | D20: Pristine / Zavala | G20: Zavala has his guys starting to felt Building 3 (Type 3). They have shingles on all amenities and garages. Building 2 also has shingles on it and now needs only the metal roofing. Jonathan also has sent us the material list for the metal he will be needing. | H20: Call Jonathan, and make sure he has guys on site to unload truck of siding. (Carefully)
B21: Dloniak House | C21: Crawl Diddy | D21: Pinnacle | G21: Huntley - Bricking Chimney & House , PEM (plumbing)- waiting on tubs / (electrical) - lighting in kitchen and porches / (HVAC) - relocating lines & gas lines, Steve (Pro Chem) - after PME finished | H21: Inspections? Getting tied into city- Hub cast iron? Gas Lines? Temp power? Structural Protection infront of plumbing fixtures in garages
B22: Woodfield - BD3 | C22: Joe | G22: Should finish 3/7/25
B28: Upcoming Projects (Start Date) | C28: Project Manager | D28: Subcontractor | F28: Customer Contact | G28: Weekly Planning Summary (Materials Ordered/Arrival Date/Change Order Submission Needed/Unsafe Conditions/Opportuities) | H28: Action Items This Week | I28: Estimated Start Date
B30: Aaron Mills | C30: Chris | D30: Pristine | F30: Brandon | G30: Framing in Process
B31: Jeffries -DHIC | C31: Joe
B32: Avonlea - DHIC | C32: Joe
B33: Sedgbrook - DHIC | C33: Joe
B34: Piney Pointe - BD3 | C34: Joe
B35: Brookside - BD3 | C35: Joe
B36: Woodfield - BD3 | C36: Joe
B37: Burnside - BD3 | C37: Joe
B38: Pipeline/Bids | C38: Project Manager | D38: Anticipated Subcontractor | E38: Estimated Start Date | F38: Customer Contact | G38: Bid Status | H38: Action Needed/Comments | I38: Estimated Start Date
B40: PPM - Regal Oaks | F40: Jason Buffkin | G40: Resent Estimate on 5-28-24 - OCN
B41: PPM-Kings Crossing | C41: Not KW | F41: Buffkin | G41: Stair replacement, site steps, sidewalk plates
B42: PPM - Plantation Village | C42: Not KW | F42: Jason Buffkin | G42: Roofing, Windows, Dumpster Fence, Mailbox Posts, 8x8
B44: PPM - Little Pee Dee Manor | C44: Not KW | F44: Jason Buffkin | G44: Gazebo Enclosure, Fountain pricing
B45: PPM - Churchwood Apts | C45: Not KW | F45: Jason Buffkin | G45: 2 story bay window replacement , accent siding, aluminum columns per PM
B46: PPM - Greenfield | C46: Not KW | F46: Jason Buffkin | G46: Storage room doors, roof replacement, siding pricing per building
B47: KMW - Hartwood Village | C47: Not KW | G47: Roofing, windows, interior doors, hardware, dumpster fence | H47: Waiting on pricing back on interior doors/windows from GCL, ABC
B48: PPM - Westridge Apts. | C48: Not KW | F48: Jason Buffkin
B49: HRP Murrayville
...

Sheet 4.25.25
B2: Team Meeting
B3: 4.25.25
B4: Present: Wes, Oscar, Joe, Carson & Stephanie & Rebecca (Septet Team, PRESENT) - we need more space, more chairs - Chris on Phone, Sick Boi
B5: Topics
B6: 1.) | C6: Weekly: Sub calendar update/Daily Job Sheets/Photos Uploaded
B7: 2.) | C7: Contract Log
B8: 3.) | C8: Alarm/Doors/Gates in 208 - does everyone know how to operate
B9: 4.) | C9: Invoice review
B10: 5.) | C10: Jesus, JSH Update
B11: 6.) | C11: Change Order Review
B12: 7.) | C12: Pay App Review - Bond Deal Little Jobs Done?
B13: 8.) | C13: Reminder - Add notes in memo line of estimate/CO emailed to customer
B14: 9.) | C14: Make sure all completed jobs are billed
B15: PROJECTS
B16: Current Projects (Start Date) | C16: Project Manager (always Chris) | D16: Subcontractor & Schedule THIS WEEK | E16: Subcontractor & Schedule NEXT WEEK/FUTURE | F16: Date Inventory Recorded | G16: Weekly Job Summary (Materials Ordered/Arrival Date/Work Performed/Action Taken) | H16: Action Items Next Week (Change Order Submission Needed/Unsafe Conditions/Materials/Opportuities) | I16: Estimated Job Completion Date | J16: CONTRACTS
B17: HRP Brightwood (4/2023) | C17: Chris | D17: Pristine | G17: Punch lists for Building 7 & 8 are ready, still waiting on the list from HRP to close out 5 & 6. When we have Siks guys back out there they need to seal the gutter that is leaking on 5. Chris will schedule them for later this week. We also need to get some siding to replace the wall they have been pulling off of in Building 10. | H17: Need to get the siding to replenish the wall they have been pulling off of, also get them scheduled to start the punch work. | I17: 45505 | J17: Done
B18: Pines @ Peach | C18: Joe | D18: Pristine | G18: Outside of 3 done / Working on Outside of 2 - KMW has Pissed off the owners. Change order for Ceilings at top floors & Breezeways has been approved. 2 crews are working on re-insulating the windows on backside on buildings 3 and 2 Also have the same crews working on the breezeways Along with putting in flashing and 2x10 in place (flashing taped and flex taped all joints along with ty-vec work) (Porches are back flush on buildings 2 & 3) | H18: CHANGE ORDERS??? | J18: Done
B19: Mountain Glen | C19: Chris | D19: Pristine / Rigo | G19: Rigo was installing doors in the UFAS units, sample walls for siding have been hung on building 144 for viewing. Siding order will ship 12/3 and will arrive 12/5 - 12/6. Last truck of doors was delivered by Sik Sunday 12/1. Consolidate containers on site so that we have room to store our siding, and need to be prepared to unload siding when it arrives. | H19: Need to find out what JGBR will be doing at Mountain Glen with Phillip, weather it is exterior work or interior work. Confirm if exterior doors are in the trailer Sik hauled up Sunday.
B20: Holbrook | C20: Chris | D20: Pristine / Zavala | G20: Zavala has his guys starting to felt Building 3 (Type 3). They have shingles on all amenities and garages. Building 2 also has shingles on it and now needs only the metal roofing. Jonathan also has sent us the material list for the metal he will be needing. | H20: Call Jonathan, and make sure he has guys on site to unload truck of siding. (Carefully)
B21: Dloniak House | C21: Crawl Diddy | D21: Pinnacle | G21: Huntley - Bricking Chimney & House , PEM (plumbing)- waiting on tubs / (electrical) - lighting in kitchen and porches / (HVAC) - relocating lines & gas lines, Steve (Pro Chem) - after PME finished | H21: Inspections? Getting tied into city- Hub cast iron? Gas Lines? Temp power? Structural Protection infront of plumbing fixtures in garages
B22: Woodfield - BD3 | C22: Joe | G22: Should finish 3/7/25
B25: Upcoming Projects (Start Date) | C25: Project Manager | D25: Subcontractor | F25: Customer Contact | G25: Weekly Planning Summary (Materials Ordered/Arrival Date/Change Order Submission Needed/Unsafe Conditions/Opportuities) | H25: Action Items This Week | I25: Estimated Start Date
B27: Aaron Mills | C27: Chris | D27: Pristine | F27: Brandon | G27: Framing in Process
B28: Jeffries -DHIC | C28: Joe
B29: Avonlea - DHIC | C29: Joe
B30: Sedgbrook - DHIC | C30: Joe
B31: Piney Pointe - BD3 | C31: Joe
B32: Brookside - BD3 | C32: Joe
B33: Woodfield - BD3 | C33: Joe
B34: Burnside - BD3 | C34: Joe
B35: Pipeline/Bids | C35: Project Manager | D35: Anticipated Subcontractor | E35: Estimated Start Date | F35: Customer Contact | G35: Bid Status | H35: Action Needed/Comments | I35: Estimated Start Date
B37: PPM - Regal Oaks | F37: Jason Buffkin | G37: Resent Estimate on 5-28-24 - OCN
B38: PPM-Kings Crossing | C38: Not KW | F38: Buffkin | G38: Stair replacement, site steps, sidewalk plates
B39: PPM - Plantation Village | C39: Not KW | F39: Jason Buffkin | G39: Roofing, Windows, Dumpster Fence, Mailbox Posts, 8x8
B41: PPM - Little Pee Dee Manor | C41: Not KW | F41: Jason Buffkin | G41: Gazebo Enclosure, Fountain pricing
B42: PPM - Churchwood Apts | C42: Not KW | F42: Jason Buffkin | G42: 2 story bay window replacement , accent siding, aluminum columns per PM
B43: PPM - Greenfield | C43: Not KW | F43: Jason Buffkin | G43: Storage room doors, roof replacement, siding pricing per building
B44: KMW - Hartwood Village | C44: Not KW | G44: Roofing, windows, interior doors, hardware, dumpster fence | H44: Waiting on pricing back on interior doors/windows from GCL, ABC
B45: PPM - Westridge Apts. | C45: Not KW | F45: Jason Buffkin
B46: HRP Murrayville
...

Sheet 3-12.25
B2: Team Meeting
B3: 3.12.25
B4: Present: Wes, Oscar, Chris, Joe, Carson & Stephanie & Rebecca (Septet Team, PRESENT) - we need more space, more chairs
B5: Topics
B6: 1.) | C6: Weekly: Sub calendar update/Daily Job Sheets/Photos Uploaded
B7: 2.) | C7: Calendar - use to help track Change Order Work
B8: 3.) | C8: Signed, CLOSING on Building for down the street
B9: 4.)
B10: 5.)
B11: 6.)
B12: 7.) | C12: Reminder - Add notes in memo line of estimate/CO emailed to customer
B13: 8.) | C13: Make sure all completed jobs are billed
B14: PROJECTS
B15: Current Projects (Start Date) | C15: Project Manager (always Chris) | D15: Subcontractor & Schedule THIS WEEK | E15: Subcontractor & Schedule NEXT WEEK/FUTURE | F15: Date Inventory Recorded | G15: Weekly Job Summary (Materials Ordered/Arrival Date/Work Performed/Action Taken) | H15: Action Items Next Week (Change Order Submission Needed/Unsafe Conditions/Materials/Opportuities) | I15: Estimated Job Completion Date | J15: CONTRACTS
B16: HRP Brightwood (4/2023) | C16: Chris | D16: Pristine | G16: Punch lists for Building 7 & 8 are ready, still waiting on the list from HRP to close out 5 & 6. When we have Siks guys back out there they need to seal the gutter that is leaking on 5. Chris will schedule them for later this week. We also need to get some siding to replace the wall they have been pulling off of in Building 10. | H16: Need to get the siding to replenish the wall they have been pulling off of, also get them scheduled to start the punch work. | I16: 45505 | J16: Done
B17: Pines @ Peach | C17: Joe | D17: Pristine | G17: Outside of 3 done / Working on Outside of 2 - KMW has Pissed off the owners. Change order for Ceilings at top floors & Breezeways has been approved. 2 crews are working on re-insulating the windows on backside on buildings 3 and 2 Also have the same crews working on the breezeways Along with putting in flashing and 2x10 in place (flashing taped and flex taped all joints along with ty-vec work) (Porches are back flush on buildings 2 & 3) | H17: CHANGE ORDERS??? | J17: Done
B18: Mountain Glen | C18: Chris | D18: Pristine / Rigo | G18: Rigo was installing doors in the UFAS units, sample walls for siding have been hung on building 144 for viewing. Siding order will ship 12/3 and will arrive 12/5 - 12/6. Last truck of doors was delivered by Sik Sunday 12/1. Consolidate containers on site so that we have room to store our siding, and need to be prepared to unload siding when it arrives. | H18: Need to find out what JGBR will be doing at Mountain Glen with Phillip, weather it is exterior work or interior work. Confirm if exterior doors are in the trailer Sik hauled up Sunday.
B19: Holbrook | C19: Chris | D19: Pristine / Zavala | G19: Zavala has his guys starting to felt Building 3 (Type 3). They have shingles on all amenities and garages. Building 2 also has shingles on it and now needs only the metal roofing. Jonathan also has sent us the material list for the metal he will be needing. | H19: Call Jonathan, and make sure he has guys on site to unload truck of siding. (Carefully)
B20: Dloniak House | C20: Crawl Diddy | D20: Pinnacle | G20: 3rd party Footing Inspection for Pinnacle Footers due to bad weather and emailed a copy of the Inspection to City of Greensboro (James Wolffe) / (Huntley Brothers) are wrapping up foundation perimeter (CMU block, brick and mortar) *Trash Dumpster is on site along with porty potty* CONTACTED Castro (framer) & Riverside Truss - Cliff (trusses) they want to meet 12/24 at 9AM and call Steve (Pro-Chem) for Termite spray before fondation inspection | H20: HOA Approval for Shingle and Metal color / Cables at front of site need to be burried lower for driveway (Call contacts on email)
B21: Woodfield - BD3 | C21: Joe | G21: Should finish 3/7/25
B24: Upcoming Projects (Start Date) | C24: Project Manager | D24: Subcontractor | F24: Customer Contact | G24: Weekly Planning Summary (Materials Ordered/Arrival Date/Change Order Submission Needed/Unsafe Conditions/Opportuities) | H24: Action Items This Week | I24: Estimated Start Date
B26: Aaron Mills | C26: Chris | D26: ? | G26: Framing in Process
B27: Jeffries -DHIC | C27: Joe
B28: Avonlea - DHIC | C28: Joe
B29: Sedgbrook - DHIC | C29: Joe
B30: Piney Pointe - BD3 | C30: Joe
B31: Brookside - BD3 | C31: Joe
B32: Woodfield - BD3 | C32: Joe
B33: Burnside - BD3 | C33: Joe
B34: Pipeline/Bids | C34: Project Manager | D34: Anticipated Subcontractor | E34: Estimated Start Date | F34: Customer Contact | G34: Bid Status | H34: Action Needed/Comments | I34: Estimated Start Date
B36: PPM - Regal Oaks | F36: Jason Buffkin | G36: Resent Estimate on 5-28-24 - OCN
B37: PPM-Kings Crossing | C37: Not KW | F37: Buffkin | G37: Stair replacement, site steps, sidewalk plates
B38: PPM - Plantation Village | C38: Not KW | F38: Jason Buffkin | G38: Roofing, Windows, Dumpster Fence, Mailbox Posts, 8x8
B40: PPM - Little Pee Dee Manor | C40: Not KW | F40: Jason Buffkin | G40: Gazebo Enclosure, Fountain pricing
B41: PPM - Churchwood Apts | C41: Not KW | F41: Jason Buffkin | G41: 2 story bay window replacement , accent siding, aluminum columns per PM
B42: PPM - Greenfield | C42: Not KW | F42: Jason Buffkin | G42: Storage room doors, roof replacement, siding pricing per building
B43: KMW - Hartwood Village | C43: Not KW | G43: Roofing, windows, interior doors, hardware, dumpster fence | H43: Waiting on pricing back on interior doors/windows from GCL, ABC
B44: PPM - Westridge Apts. | C44: Not KW | F44: Jason Buffkin
B45: HRP Murrayville
B46: KMW - Fairway PH2 | G46: Bid sent to C. Binkowski on 11-10-22 *OCN 11/10/22 * *Again 10-23-24*
...

Sheet 3-26.25 
B2: Team Meeting
B3: 45742
B4: Present: Wes, Oscar, Joe, Carson & Stephanie & Rebecca (Septet Team, PRESENT) - we need more space, more chairs
B5: Topics
B6: 1.) | C6: Weekly: Sub calendar update/Daily Job Sheets/Photos Uploaded
B7: 2.) | C7: Calendar - use to help track Change Order Work
B8: 3.) | C8: Flooring - 3/28, 2 offices and conference room in back
B9: 4.) | C9: 208 Door codes
B10: 5.) | C10: Invoices -
B11: 6.) | C11: Vendor set -up
B12: 7.) | C12: Reminder - Add notes in memo line of estimate/CO emailed to customer
B13: 8.) | C13: Make sure all completed jobs are billed
B14: PROJECTS
B15: Current Projects (Start Date) | C15: Project Manager (always Chris) | D15: Subcontractor & Schedule THIS WEEK | E15: Subcontractor & Schedule NEXT WEEK/FUTURE | F15: Date Inventory Recorded | G15: Weekly Job Summary (Materials Ordered/Arrival Date/Work Performed/Action Taken) | H15: Action Items Next Week (Change Order Submission Needed/Unsafe Conditions/Materials/Opportuities) | I15: Estimated Job Completion Date | J15: CONTRACTS
B16: HRP Brightwood (4/2023) | C16: Chris | D16: Pristine | G16: Punch lists for Building 7 & 8 are ready, still waiting on the list from HRP to close out 5 & 6. When we have Siks guys back out there they need to seal the gutter that is leaking on 5. Chris will schedule them for later this week. We also need to get some siding to replace the wall they have been pulling off of in Building 10. | H16: Need to get the siding to replenish the wall they have been pulling off of, also get them scheduled to start the punch work. | I16: 45505 | J16: Done
B17: Pines @ Peach | C17: Joe | D17: Pristine | G17: Outside of 3 done / Working on Outside of 2 - KMW has Pissed off the owners. Change order for Ceilings at top floors & Breezeways has been approved. 2 crews are working on re-insulating the windows on backside on buildings 3 and 2 Also have the same crews working on the breezeways Along with putting in flashing and 2x10 in place (flashing taped and flex taped all joints along with ty-vec work) (Porches are back flush on buildings 2 & 3) | H17: CHANGE ORDERS??? | J17: Done
B18: Mountain Glen | C18: Chris | D18: Pristine / Rigo | G18: Rigo was installing doors in the UFAS units, sample walls for siding have been hung on building 144 for viewing. Siding order will ship 12/3 and will arrive 12/5 - 12/6. Last truck of doors was delivered by Sik Sunday 12/1. Consolidate containers on site so that we have room to store our siding, and need to be prepared to unload siding when it arrives. | H18: Need to find out what JGBR will be doing at Mountain Glen with Phillip, weather it is exterior work or interior work. Confirm if exterior doors are in the trailer Sik hauled up Sunday.
B19: Holbrook | C19: Chris | D19: Pristine / Zavala | G19: Zavala has his guys starting to felt Building 3 (Type 3). They have shingles on all amenities and garages. Building 2 also has shingles on it and now needs only the metal roofing. Jonathan also has sent us the material list for the metal he will be needing. | H19: Call Jonathan, and make sure he has guys on site to unload truck of siding. (Carefully)
B20: Dloniak House | C20: Crawl Diddy | D20: Pinnacle | G20: Huntley - Bricking Chimney & House , PEM (plumbing)- waiting on tubs / (electrical) - lighting in kitchen and porches / (HVAC) - relocating lines & gas lines, Steve (Pro Chem) - after PME finished | H20: Inspections? Getting tied into city- Hub cast iron? Gas Lines? Temp power? Structural Protection infront of plumbing fixtures in garages
B21: Woodfield - BD3 | C21: Joe | G21: Should finish 3/7/25
B24: Upcoming Projects (Start Date) | C24: Project Manager | D24: Subcontractor | F24: Customer Contact | G24: Weekly Planning Summary (Materials Ordered/Arrival Date/Change Order Submission Needed/Unsafe Conditions/Opportuities) | H24: Action Items This Week | I24: Estimated Start Date
B26: Aaron Mills | C26: Chris | D26: ? | G26: Framing in Process
B27: Jeffries -DHIC | C27: Joe
B28: Avonlea - DHIC | C28: Joe
B29: Sedgbrook - DHIC | C29: Joe
B30: Piney Pointe - BD3 | C30: Joe
B31: Brookside - BD3 | C31: Joe
B32: Woodfield - BD3 | C32: Joe
B33: Burnside - BD3 | C33: Joe
B34: Pipeline/Bids | C34: Project Manager | D34: Anticipated Subcontractor | E34: Estimated Start Date | F34: Customer Contact | G34: Bid Status | H34: Action Needed/Comments | I34: Estimated Start Date
B36: PPM - Regal Oaks | F36: Jason Buffkin | G36: Resent Estimate on 5-28-24 - OCN
B37: PPM-Kings Crossing | C37: Not KW | F37: Buffkin | G37: Stair replacement, site steps, sidewalk plates
B38: PPM - Plantation Village | C38: Not KW | F38: Jason Buffkin | G38: Roofing, Windows, Dumpster Fence, Mailbox Posts, 8x8
B40: PPM - Little Pee Dee Manor | C40: Not KW | F40: Jason Buffkin | G40: Gazebo Enclosure, Fountain pricing
B41: PPM - Churchwood Apts | C41: Not KW | F41: Jason Buffkin | G41: 2 story bay window replacement , accent siding, aluminum columns per PM
B42: PPM - Greenfield | C42: Not KW | F42: Jason Buffkin | G42: Storage room doors, roof replacement, siding pricing per building
B43: KMW - Hartwood Village | C43: Not KW | G43: Roofing, windows, interior doors, hardware, dumpster fence | H43: Waiting on pricing back on interior doors/windows from GCL, ABC
B44: PPM - Westridge Apts. | C44: Not KW | F44: Jason Buffkin
B45: HRP Murrayville
B46: KMW - Fairway PH2 | G46: Bid sent to C. Binkowski on 11-10-22 *OCN 11/10/22 * *Again 10-23-24*
...

Sheet 2-28-25
B2: Team Meeting
B3: 2.28.25
B4: Present: Wes, Oscar, Chris, Joe, Carson & Stephanie & Rebecca (Septet Team, PRESENT) - we need more space, more chairs
B5: Topics
B6: 1.) | C6: Weekly: Sub calendar update/Daily Job Sheets/Photos Uploaded
B7: 2.) | C7: Calendar - use to help track Change Order Work
B8: 3.) | C8: Signed, CLOSING on Building for down the street
B9: 4.) | C9: Review Employee P&P
B10: 5.)
B11: 6.)
B12: 7.) | C12: Reminder - Add notes in memo line of estimate/CO emailed to customer
B13: 8.) | C13: Make sure all completed jobs are billed
B14: PROJECTS
B15: Current Projects (Start Date) | C15: Project Manager (always Chris) | D15: Subcontractor & Schedule THIS WEEK | E15: Subcontractor & Schedule NEXT WEEK/FUTURE | F15: Date Inventory Recorded | G15: Weekly Job Summary (Materials Ordered/Arrival Date/Work Performed/Action Taken) | H15: Action Items Next Week (Change Order Submission Needed/Unsafe Conditions/Materials/Opportuities) | I15: Estimated Job Completion Date | J15: CONTRACTS
B16: HRP Brightwood (4/2023) | C16: Chris | D16: Pristine | G16: Punch lists for Building 7 & 8 are ready, still waiting on the list from HRP to close out 5 & 6. When we have Siks guys back out there they need to seal the gutter that is leaking on 5. Chris will schedule them for later this week. We also need to get some siding to replace the wall they have been pulling off of in Building 10. | H16: Need to get the siding to replenish the wall they have been pulling off of, also get them scheduled to start the punch work. | I16: 45505 | J16: Done
B17: Pines @ Peach | C17: Joe | D17: Pristine | G17: Outside of 3 done / Working on Outside of 2 - KMW has Pissed off the owners. Change order for Ceilings at top floors & Breezeways has been approved. 2 crews are working on re-insulating the windows on backside on buildings 3 and 2 Also have the same crews working on the breezeways Along with putting in flashing and 2x10 in place (flashing taped and flex taped all joints along with ty-vec work) (Porches are back flush on buildings 2 & 3) | H17: CHANGE ORDERS??? | J17: Done
B18: Mountain Glen | C18: Chris | D18: Pristine / Rigo | G18: Rigo was installing doors in the UFAS units, sample walls for siding have been hung on building 144 for viewing. Siding order will ship 12/3 and will arrive 12/5 - 12/6. Last truck of doors was delivered by Sik Sunday 12/1. Consolidate containers on site so that we have room to store our siding, and need to be prepared to unload siding when it arrives. | H18: Need to find out what JGBR will be doing at Mountain Glen with Phillip, weather it is exterior work or interior work. Confirm if exterior doors are in the trailer Sik hauled up Sunday.
B19: Holbrook | C19: Chris | D19: Pristine / Zavala | G19: Zavala has his guys starting to felt Building 3 (Type 3). They have shingles on all amenities and garages. Building 2 also has shingles on it and now needs only the metal roofing. Jonathan also has sent us the material list for the metal he will be needing. | H19: Call Jonathan, and make sure he has guys on site to unload truck of siding. (Carefully)
B20: Dloniak House | C20: Crawl Diddy | D20: Pinnacle | G20: 3rd party Footing Inspection for Pinnacle Footers due to bad weather and emailed a copy of the Inspection to City of Greensboro (James Wolffe) / (Huntley Brothers) are wrapping up foundation perimeter (CMU block, brick and mortar) *Trash Dumpster is on site along with porty potty* CONTACTED Castro (framer) & Riverside Truss - Cliff (trusses) they want to meet 12/24 at 9AM and call Steve (Pro-Chem) for Termite spray before fondation inspection | H20: HOA Approval for Shingle and Metal color / Cables at front of site need to be burried lower for driveway (Call contacts on email)
B21: Woodfield - BD3 | C21: Joe | G21: Should finish 3/7/25
B24: Upcoming Projects (Start Date) | C24: Project Manager | D24: Subcontractor | F24: Customer Contact | G24: Weekly Planning Summary (Materials Ordered/Arrival Date/Change Order Submission Needed/Unsafe Conditions/Opportuities) | H24: Action Items This Week | I24: Estimated Start Date
B26: Aaron Mills | C26: Chris | D26: ? | G26: Framing in Process
B27: Jeffries -DHIC | C27: Joe
B28: Avonlea - DHIC | C28: Joe
B29: Sedgbrook - DHIC | C29: Joe
B30: Piney Pointe - BD3 | C30: Joe
B31: Brookside - BD3 | C31: Joe
B32: Woodfield - BD3 | C32: Joe
B33: Burnside - BD3 | C33: Joe
B34: Pipeline/Bids | C34: Project Manager | D34: Anticipated Subcontractor | E34: Estimated Start Date | F34: Customer Contact | G34: Bid Status | H34: Action Needed/Comments | I34: Estimated Start Date
B36: PPM - Regal Oaks | F36: Jason Buffkin | G36: Resent Estimate on 5-28-24 - OCN
B37: PPM-Kings Crossing | C37: Not KW | F37: Buffkin | G37: Stair replacement, site steps, sidewalk plates
B38: PPM - Plantation Village | C38: Not KW | F38: Jason Buffkin | G38: Roofing, Windows, Dumpster Fence, Mailbox Posts, 8x8
B40: PPM - Little Pee Dee Manor | C40: Not KW | F40: Jason Buffkin | G40: Gazebo Enclosure, Fountain pricing
B41: PPM - Churchwood Apts | C41: Not KW | F41: Jason Buffkin | G41: 2 story bay window replacement , accent siding, aluminum columns per PM
B42: PPM - Greenfield | C42: Not KW | F42: Jason Buffkin | G42: Storage room doors, roof replacement, siding pricing per building
B43: KMW - Hartwood Village | C43: Not KW | G43: Roofing, windows, interior doors, hardware, dumpster fence | H43: Waiting on pricing back on interior doors/windows from GCL, ABC
B44: PPM - Westridge Apts. | C44: Not KW | F44: Jason Buffkin
B45: HRP Murrayville
B46: KMW - Fairway PH2 | G46: Bid sent to C. Binkowski on 11-10-22 *OCN 11/10/22 * *Again 10-23-24*
...

Sheet 12-2-24
B2: Team Meeting
B3: 12.2.24
B4: Present: Wes, Oscar, Chris, Joe, Carson & Stephanie (Seal Team 6, PRESENT)
B5: Topics
B6: 1.) | C6: Weekly: Sub calendar update/Daily Job Sheets/Photos Uploaded
B7: 2.) | C7: Calendar - use to help track Change Order Work
B8: 3.) | C8: Vehicles - keep oil changed, some inspections due 12/31 service truck
B9: 4.) | C9: Contract log -Need - CO Pungo waiting on this, DHIC, Mountain Glen
B10: 5.) | C10: Container lock keys on all vehicle key rings
B11: 6.) | C11: Retail: please add address of work performed
B12: 7.) | C12: Reminder - Add notes in memo line of estimate/CO emailed to customer
B13: 8.) | C13: Make sure all completed jobs are billed
B14: PROJECTS
B15: Current Projects (Start Date) | C15: Project Manager (always Chris) | D15: Subcontractor & Schedule THIS WEEK | E15: Subcontractor & Schedule NEXT WEEK/FUTURE | F15: Date Inventory Recorded | G15: Weekly Job Summary (Materials Ordered/Arrival Date/Work Performed/Action Taken) | H15: Action Items Next Week (Change Order Submission Needed/Unsafe Conditions/Materials/Opportuities) | I15: Estimated Job Completion Date | J15: CONTRACTS
B16: HRP Brightwood (4/2023) | C16: Chris | D16: Pristine | G16: Punch lists for Building 7 & 8 are ready, still waiting on the list from HRP to close out 5 & 6. When we have Siks guys back out there they need to seal the gutter that is leaking on 5. Chris will schedule them for later this week. We also need to get some siding to replace the wall they have been pulling off of in Building 10. | H16: Need to get the siding to replenish the wall they have been pulling off of, also get them scheduled to start the punch work. | I16: 45505 | J16: Done
B17: KMW Townsend Trace | C17: Chris | G17: Gutter Repair, Rigo | H17: Maybe this needs to be done on a Saturday | J17: Done
B18: Pines @ Peach | C18: Joe | D18: Pristine | G18: Outside of 3 done / Working on Outside of 2 - KMW has Pissed off the owners. Change order for Ceilings at top floors & Breezeways has been approved. 2 crews are working on re-insulating the windows on backside on buildings 3 and 2 Also have the same crews working on the breezeways Along with putting in flashing and 2x10 in place (flashing taped and flex taped all joints along with ty-vec work) (Porches are back flush on buildings 2 & 3) | H18: CHANGE ORDERS??? | J18: Done
B19: (KMW)Wakefield (5/2023) | C19: Joe | D19: Pristine | G19: Pristine was to re-install the fence infront of building 2, needed to widen the fence. - OCN Dropped off grate and it fits perfectly inside building (Wes welded it) | J19: Done
B20: KMW Evoke | C20: Chris | D20: Rogelio/Hillstone | G20: Rain delays for Hillstone. Rogelio work is change orders we will charge for. SA to send CO to Josh.
B21: KMW Pungo | C21: Joe | D21: Pristine /Concrete Manuel | G21: Want Stair rails done by wednsday, want to start ramp rails on Monday. Carson took trailer load of handrails 12/10/24 and Rogelio's crew was working on them this week. 12/18/24 Handrails were finished; Wes recieved messeages and pictures on handrails in place at 7pm. | H21: Bank recieved photos of work.
B22: Gatebay | C22: Joe/ Chris | D22: Pristine | G22: Finished up, need to call in a final inspection to close out the permits in their system. Joe had gone back to install siding on the second shed there and job was closed up after that.
B23: Mountain Glen | C23: Chris | D23: Pristine / Rigo | G23: Rigo was installing doors in the UFAS units, sample walls for siding have been hung on building 144 for viewing. Siding order will ship 12/3 and will arrive 12/5 - 12/6. Last truck of doors was delivered by Sik Sunday 12/1. Consolidate containers on site so that we have room to store our siding, and need to be prepared to unload siding when it arrives. | H23: Need to find out what JGBR will be doing at Mountain Glen with Phillip, weather it is exterior work or interior work. Confirm if exterior doors are in the trailer Sik hauled up Sunday.
B24: Holbrook | C24: Chris | D24: Pristine / Zavala | G24: Zavala has his guys starting to felt Building 3 (Type 3). They have shingles on all amenities and garages. Building 2 also has shingles on it and now needs only the metal roofing. Jonathan also has sent us the material list for the metal he will be needing. | H24: Call Jonathan, and make sure he has guys on site to unload truck of siding. (Carefully)
